<sdf version='1.6'>
  <world name='default'>
    <light name='sun' type='directional'>
      <cast_shadows>1</cast_shadows>
      <pose frame=''>0 0 10 0 -0 0</pose>
      <diffuse>0.8 0.8 0.8 1</diffuse>
      <specular>0.1 0.1 0.1 1</specular>
      <attenuation>
        <range>1000</range>
        <constant>0.9</constant>
        <linear>0.01</linear>
        <quadratic>0.001</quadratic>
      </attenuation>
      <direction>-0.5 0.5 -1</direction>
    </light>
    <model name='ground_plane'>
      <static>1</static>
      <link name='link'>
        <collision name='collision'>
          <geometry>
            <plane>
              <normal>0 0 1</normal>
              <size>100 100</size>
            </plane>
          </geometry>
          <surface>
            <friction>
              <ode>
                <mu>1</mu>
                <mu2>1</mu2>
              </ode>
              <torsional>
                <ode/>
              </torsional>
            </friction>
            <contact>
              <ode/>
            </contact>
            <bounce/>
          </surface>
          <max_contacts>10</max_contacts>
        </collision>
        <visual name='visual'>
          <cast_shadows>0</cast_shadows>
          <geometry>
            <plane>
              <normal>0 0 1</normal>
              <size>100 100</size>
            </plane>
          </geometry>
          <material>
            <script>
              <uri>file://media/materials/scripts/gazebo.material</uri>
              <name>Gazebo/Grey</name>
            </script>
          </material>
        </visual>
        <self_collide>0</self_collide>
        <kinematic>0</kinematic>
        <gravity>1</gravity>
        <enable_wind>0</enable_wind>
      </link>
    </model>
    <gravity>0 0 -9.8</gravity>
    <magnetic_field>6e-06 2.3e-05 -4.2e-05</magnetic_field>
    <atmosphere type='adiabatic'/>
    <physics name='default_physics' default='0' type='ode'>
      <max_step_size>0.001</max_step_size>
      <real_time_factor>1</real_time_factor>
      <real_time_update_rate>1000</real_time_update_rate>
    </physics>
    <scene>
      <ambient>0.4 0.4 0.4 1</ambient>
      <background>0.7 0.7 0.7 1</background>
      <shadows>1</shadows>
    </scene>
    <spherical_coordinates>
      <surface_model>EARTH_WGS84</surface_model>
      <latitude_deg>0</latitude_deg>
      <longitude_deg>0</longitude_deg>
      <elevation>0</elevation>
      <heading_deg>0</heading_deg>
    </spherical_coordinates>
    <gui fullscreen='0'>
      <camera name='user_camera'>
        <pose frame=''>-0.804595 12.8282 12.4662 0 0.732 -1.6188</pose>
        <view_controller>orbit</view_controller>
        <projection_type>perspective</projection_type>
      </camera>
    </gui>
    <wind/>
    <model name='logger1'>
      <link name='logger-chassis'>
        <pose frame=''>0 0 0 0 -0 0</pose>
        <inertial>
          <pose frame=''>0.005952 0 -0.002381 0 -0 0</pose>
          <mass>2.1</mass>
          <inertia>
            <ixx>0.0332188</ixx>
            <ixy>0</ixy>
            <ixz>0.000595238</ixz>
            <iyy>0.0347069</iyy>
            <iyz>0</iyz>
            <izz>0.0640521</izz>
          </inertia>
        </inertial>
        <collision name='logger-chassis_collision'>
          <pose frame=''>0 0 0 0 -0 0</pose>
          <geometry>
            <cylinder>
              <length>0.1</length>
              <radius>0.25</radius>
            </cylinder>
          </geometry>
          <surface>
            <contact>
              <ode/>
            </contact>
            <friction>
              <ode>
                <mu>0.5</mu>
                <mu2>0.5</mu2>
              </ode>
              <torsional>
                <ode/>
              </torsional>
            </friction>
            <bounce/>
          </surface>
          <max_contacts>10</max_contacts>
        </collision>
        <collision name='logger-chassis_fixed_joint_lump__logger-caster_collision_1'>
          <pose frame=''>0.125 0 -0.05 0 -0 0</pose>
          <geometry>
            <sphere>
              <radius>0.04</radius>
            </sphere>
          </geometry>
          <surface>
            <contact>
              <ode/>
            </contact>
            <friction>
              <ode>
                <mu>0</mu>
                <mu2>0</mu2>
              </ode>
              <torsional>
                <ode/>
              </torsional>
            </friction>
            <bounce/>
          </surface>
          <max_contacts>10</max_contacts>
        </collision>
        <visual name='logger-chassis_visual'>
          <pose frame=''>0 0 0 0 -0 0</pose>
          <geometry>
            <cylinder>
              <length>0.1</length>
              <radius>0.25</radius>
            </cylinder>
          </geometry>
          <material>
            <script>
              <name>Gazebo/White</name>
              <uri>file://media/materials/scripts/gazebo.material</uri>
            </script>
          </material>
        </visual>
        <visual name='logger-chassis_fixed_joint_lump__logger-caster_visual_1'>
          <pose frame=''>0.125 0 -0.05 0 -0 0</pose>
          <geometry>
            <sphere>
              <radius>0.04</radius>
            </sphere>
          </geometry>
          <material>
            <script>
              <name>Gazebo/Grey</name>
              <uri>file://media/materials/scripts/gazebo.material</uri>
            </script>
          </material>
        </visual>
        <velocity_decay/>
        <gravity>1</gravity>
        <velocity_decay/>
        <self_collide>0</self_collide>
        <enable_wind>0</enable_wind>
        <kinematic>0</kinematic>
      </link>
      <link name='logger-hat'>
        <pose frame=''>0 0 0.1 0 -0 0</pose>
        <inertial>
          <pose frame=''>0 0 0.04 0 -0 0</pose>
          <mass>0.5</mass>
          <inertia>
            <ixx>0.000466667</ixx>
            <ixy>0</ixy>
            <ixz>0</ixz>
            <iyy>0.000466667</iyy>
            <iyz>0</iyz>
            <izz>0.0001</izz>
          </inertia>
        </inertial>
        <collision name='logger-hat_collision'>
          <pose frame=''>0 0 0 0 -0 0</pose>
          <geometry>
            <cylinder>
              <length>0.1</length>
              <radius>0.02</radius>
            </cylinder>
          </geometry>
          <surface>
            <contact>
              <ode/>
            </contact>
            <friction>
              <ode>
                <mu>0</mu>
                <mu2>0</mu2>
              </ode>
              <torsional>
                <ode/>
              </torsional>
            </friction>
            <bounce/>
          </surface>
          <max_contacts>10</max_contacts>
        </collision>
        <visual name='logger-hat_visual'>
          <pose frame=''>0 0 0 0 -0 0</pose>
          <geometry>
            <cylinder>
              <length>0.1</length>
              <radius>0.02</radius>
            </cylinder>
          </geometry>
          <material>
            <script>
              <name>Gazebo/Red</name>
              <uri>file://media/materials/scripts/gazebo.material</uri>
            </script>
          </material>
        </visual>
        <gravity>1</gravity>
        <velocity_decay/>
        <self_collide>0</self_collide>
        <enable_wind>0</enable_wind>
        <kinematic>0</kinematic>
      </link>
      <joint name='logger-chassis2hat' type='revolute'>
        <child>logger-hat</child>
        <parent>logger-chassis</parent>
        <axis>
          <xyz>0 0 1</xyz>
          <limit>
            <lower>-1e+16</lower>
            <upper>1e+16</upper>
          </limit>
          <dynamics>
            <spring_reference>0</spring_reference>
            <spring_stiffness>0</spring_stiffness>
          </dynamics>
          <use_parent_model_frame>0</use_parent_model_frame>
        </axis>
      </joint>
      <link name='logger-left_wheel'>
        <pose frame=''>-0.125 -0.125 0 0 -0 0</pose>
        <inertial>
          <pose frame=''>0 0 0 1.5708 -0 0</pose>
          <mass>0.5</mass>
          <inertia>
            <ixx>0.00107917</ixx>
            <ixy>0</ixy>
            <ixz>0</ixz>
            <iyy>0.00107917</iyy>
            <iyz>0</iyz>
            <izz>0.002025</izz>
          </inertia>
        </inertial>
        <collision name='logger-left_wheel_collision'>
          <pose frame=''>0 0 0 1.5708 -0 0</pose>
          <geometry>
            <cylinder>
              <length>0.04</length>
              <radius>0.09</radius>
            </cylinder>
          </geometry>
          <surface>
            <contact>
              <ode/>
            </contact>
            <friction>
              <ode>
                <mu>0.99</mu>
                <mu2>0.99</mu2>
              </ode>
              <torsional>
                <ode/>
              </torsional>
            </friction>
            <bounce/>
          </surface>
          <max_contacts>10</max_contacts>
        </collision>
        <visual name='logger-left_wheel_visual'>
          <pose frame=''>0 0 0 1.5708 -0 0</pose>
          <geometry>
            <cylinder>
              <length>0.04</length>
              <radius>0.09</radius>
            </cylinder>
          </geometry>
          <material>
            <script>
              <name>Gazebo/Wood</name>
              <uri>file://media/materials/scripts/gazebo.material</uri>
            </script>
          </material>
        </visual>
        <gravity>1</gravity>
        <velocity_decay/>
        <self_collide>0</self_collide>
        <enable_wind>0</enable_wind>
        <kinematic>0</kinematic>
      </link>
      <joint name='logger-chassis2left_wheel' type='revolute'>
        <child>logger-left_wheel</child>
        <parent>logger-chassis</parent>
        <axis>
          <xyz>0 1 0</xyz>
          <limit>
            <lower>-1e+16</lower>
            <upper>1e+16</upper>
          </limit>
          <dynamics>
            <spring_reference>0</spring_reference>
            <spring_stiffness>0</spring_stiffness>
          </dynamics>
          <use_parent_model_frame>0</use_parent_model_frame>
        </axis>
      </joint>
      <link name='logger-right_wheel'>
        <pose frame=''>-0.125 0.125 0 0 -0 0</pose>
        <inertial>
          <pose frame=''>0 0 0 1.5708 -0 0</pose>
          <mass>0.5</mass>
          <inertia>
            <ixx>0.00107917</ixx>
            <ixy>0</ixy>
            <ixz>0</ixz>
            <iyy>0.00107917</iyy>
            <iyz>0</iyz>
            <izz>0.002025</izz>
          </inertia>
        </inertial>
        <collision name='logger-right_wheel_collision'>
          <pose frame=''>0 0 0 1.5708 -0 0</pose>
          <geometry>
            <cylinder>
              <length>0.04</length>
              <radius>0.09</radius>
            </cylinder>
          </geometry>
          <surface>
            <contact>
              <ode/>
            </contact>
            <friction>
              <ode>
                <mu>0.99</mu>
                <mu2>0.99</mu2>
              </ode>
              <torsional>
                <ode/>
              </torsional>
            </friction>
            <bounce/>
          </surface>
          <max_contacts>10</max_contacts>
        </collision>
        <visual name='logger-right_wheel_visual'>
          <pose frame=''>0 0 0 1.5708 -0 0</pose>
          <geometry>
            <cylinder>
              <length>0.04</length>
              <radius>0.09</radius>
            </cylinder>
          </geometry>
          <material>
            <script>
              <name>Gazebo/Wood</name>
              <uri>file://media/materials/scripts/gazebo.material</uri>
            </script>
          </material>
        </visual>
        <gravity>1</gravity>
        <velocity_decay/>
        <self_collide>0</self_collide>
        <enable_wind>0</enable_wind>
        <kinematic>0</kinematic>
      </link>
      <joint name='logger-chassis2right_wheel' type='revolute'>
        <child>logger-right_wheel</child>
        <parent>logger-chassis</parent>
        <axis>
          <xyz>0 1 0</xyz>
          <limit>
            <lower>-1e+16</lower>
            <upper>1e+16</upper>
          </limit>
          <dynamics>
            <spring_reference>0</spring_reference>
            <spring_stiffness>0</spring_stiffness>
          </dynamics>
          <use_parent_model_frame>0</use_parent_model_frame>
        </axis>
      </joint>
      <static>0</static>

      <plugin name='mecanum_controller' filename='libgazebo_ros_planar_move.so'>
  <alwaysOn>1</alwaysOn>
  <updateRate>100.0</updateRate>
  <robotNamespace>/</robotNamespace>
<!--  <leftFrontJoint>base_to_wheel1</leftFrontJoint>-->
<!--  <rightFrontJoint>base_to_wheel3</rightFrontJoint>-->
<!--  <leftRearJoint>base_to_wheel2</leftRearJoint>-->
<!--  <rightRearJoint>base_to_wheel4</rightRearJoint>-->
  <wheelSeparation>0.26</wheelSeparation>
  <wheelDiameter>0.12</wheelDiameter>
  <torque>2</torque>
  <commandTopic>logger1/cmd_vel</commandTopic>
  <odometryTopic>logger1/odom</odometryTopic>
  <odometryFrame>odom</odometryFrame>
  <robotBaseFrame>dummy</robotBaseFrame>
  <broadcastTF>1</broadcastTF>
</plugin>
      <pose frame=''>1 0 0.1 0 -0 1.57</pose>
    </model>
<!--模型 -->
    <model name='barrier'>
    <pose frame=''>0 0 0  0 0 0</pose>
      <include>
        <uri>///home/firefly/model_editor_models/real_logger</uri><!--核心-->
<!--        <uri>model://real_logger0</uri>  &lt;!&ndash;注意写法&ndash;&gt;-->
      </include>

    </model>
    <state world_name='default'>
      <sim_time>71 882000000</sim_time>
      <real_time>72 31865540</real_time>
      <wall_time>1630158879 122479512</wall_time>
      <iterations>71882</iterations>
      <model name='ground_plane'>
        <pose frame=''>0 0 0 0 -0 0</pose>
        <scale>1 1 1</scale>
        <link name='link'>
          <pose frame=''>0 0 0 0 -0 0</pose>
          <velocity>0 0 0 0 -0 0</velocity>
          <acceleration>0 0 0 0 -0 0</acceleration>
          <wrench>0 0 0 0 -0 0</wrench>
        </link>
      </model>
      <model name='logger0'>
        <pose frame=''>-1.00016 0.00658 0.09 0 -0 1.5746</pose>
        <scale>1 1 1</scale>
        <link name='logger-chassis'>
          <pose frame=''>-1.00016 0.00658 0.09 0 -0 1.5746</pose>
          <velocity>-6e-06 -0.000695 0.001742 0.01373 6.9e-05 3e-05</velocity>
          <acceleration>-0.009922 -1.42534 3.64735 1.14865 0.135474 0.291185</acceleration>
          <wrench>-0.020837 -2.99322 7.65943 0 -0 0</wrench>
        </link>
        <link name='logger-hat'>
          <pose frame=''>-1.00016 0.00658 0.19 0 -0 1.57</pose>
          <velocity>1e-06 -0.002051 0.001734 0.01381 6.9e-05 0</velocity>
          <acceleration>0.010076 -5.30726 3.46795 2.48468 0.138031 -3.6e-05</acceleration>
          <wrench>0.005038 -2.65363 1.73398 0 -0 0</wrench>
        </link>
        <link name='logger-left_wheel'>
          <pose frame=''>-0.874688 -0.117944 0.09 5e-06 0.037219 1.5746</pose>
          <velocity>8e-06 -0.000856 -6e-06 0.009921 7.9e-05 -0.001467</velocity>
          <acceleration>0.016164 -1.81441 -0.012146 -1.39289 0.316519 -2.95685</acceleration>
          <wrench>0.008082 -0.907206 -0.006073 0 -0 0</wrench>
        </link>
        <link name='logger-right_wheel'>
          <pose frame=''>-1.12469 -0.118894 0.09 -5e-06 0.035898 1.5746</pose>
          <velocity>-6e-06 -0.000859 -6e-06 0.009982 -4.6e-05 0.001574</velocity>
          <acceleration>-0.010414 -1.81566 -0.012166 -1.36451 -0.254503 3.12595</acceleration>
          <wrench>-0.005207 -0.907831 -0.006083 0 -0 0</wrench>
        </link>
      </model>
      <model name='logger1'>
        <pose frame=''>0.999837 0.006602 0.09 0 -0 1.57462</pose>
        <scale>1 1 1</scale>
        <link name='logger-chassis'>
          <pose frame=''>0.999837 0.006602 0.09 0 -0 1.57462</pose>
          <velocity>-6e-06 -0.000695 0.001741 0.013725 7e-05 2.9e-05</velocity>
          <acceleration>-0.009902 -1.42476 3.64606 1.13935 0.135898 0.291072</acceleration>
          <wrench>-0.020794 -2.99199 7.65672 0 -0 0</wrench>
        </link>
        <link name='logger-hat'>
          <pose frame=''>0.999837 0.006602 0.19 0 -0 1.57</pose>
          <velocity>1e-06 -0.002051 0.001733 0.013805 6.9e-05 0</velocity>
          <acceleration>0.010155 -5.3053 3.46672 2.47492 0.138456 -3.5e-05</acceleration>
          <wrench>0.005078 -2.65265 1.73336 0 -0 0</wrench>
        </link>
        <link name='logger-left_wheel'>
          <pose frame=''>1.12531 -0.11792 0.09 5e-06 0.037316 1.57462</pose>
          <velocity>8e-06 -0.000855 -6e-06 0.009917 7.8e-05 -0.001466</velocity>
          <acceleration>0.016184 -1.81372 -0.012146 -1.39709 0.316813 -2.9561</acceleration>
          <wrench>0.008092 -0.906861 -0.006073 0 -0 0</wrench>
        </link>
        <link name='logger-right_wheel'>
          <pose frame=''>0.875315 -0.118875 0.09 -5e-06 0.035993 1.57462</pose>
          <velocity>-6e-06 -0.000859 -6e-06 0.009979 -4.6e-05 0.001573</velocity>
          <acceleration>-0.010387 -1.81497 -0.012167 -1.36872 -0.254065 3.12514</acceleration>
          <wrench>-0.005194 -0.907485 -0.006084 0 -0 0</wrench>
        </link>
      </model>
      <light name='sun'>
        <pose frame=''>0 0 10 0 -0 0</pose>
      </light>
    </state>
  </world>
</sdf>
